Internal Server Error: /api/user/me/profile/
Traceback (most recent call last):
  File "/Users/jaewonk/Documents/whoami/whoami-env-3.9/lib/python3.9/site-packages/asgiref/sync.py", line 534, in thread_handler
    raise exc_info[1]
  File "/Users/jaewonk/Documents/whoami/whoami-env-3.9/lib/python3.9/site-packages/django/core/handlers/exception.py", line 42, in inner
    response = await get_response(request)
  File "/Users/jaewonk/Documents/whoami/whoami-env-3.9/lib/python3.9/site-packages/django/core/handlers/base.py", line 253, in _get_response_async
    response = await wrapped_callback(
  File "/Users/jaewonk/Documents/whoami/whoami-env-3.9/lib/python3.9/site-packages/asgiref/sync.py", line 479, in __call__
    ret: _R = await loop.run_in_executor(
  File "/Library/Developer/CommandLineTools/Library/Frameworks/Python3.framework/Versions/3.9/lib/python3.9/concurrent/futures/thread.py", line 52, in run
    result = self.fn(*self.args, **self.kwargs)
  File "/Users/jaewonk/Documents/whoami/whoami-env-3.9/lib/python3.9/site-packages/asgiref/sync.py", line 538, in thread_handler
    return func(*args, **kwargs)
  File "/Users/jaewonk/Documents/whoami/whoami-env-3.9/lib/python3.9/site-packages/django/views/decorators/csrf.py", line 56, in wrapper_view
    return view_func(*args, **kwargs)
  File "/Users/jaewonk/Documents/whoami/whoami-env-3.9/lib/python3.9/site-packages/django/views/generic/base.py", line 104, in view
    return self.dispatch(request, *args, **kwargs)
  File "/Users/jaewonk/Documents/whoami/whoami-env-3.9/lib/python3.9/site-packages/rest_framework/views.py", line 509, in dispatch
    response = self.handle_exception(exc)
  File "/Users/jaewonk/Documents/whoami/whoami-env-3.9/lib/python3.9/site-packages/rest_framework/views.py", line 469, in handle_exception
    self.raise_uncaught_exception(exc)
  File "/Users/jaewonk/Documents/whoami/whoami-env-3.9/lib/python3.9/site-packages/rest_framework/views.py", line 480, in raise_uncaught_exception
    raise exc
  File "/Users/jaewonk/Documents/whoami/whoami-env-3.9/lib/python3.9/site-packages/rest_framework/views.py", line 506, in dispatch
    response = handler(request, *args, **kwargs)
  File "/Users/jaewonk/Documents/whoami/whoami-env-3.9/lib/python3.9/site-packages/rest_framework/generics.py", line 208, in get
    return self.retrieve(request, *args, **kwargs)
  File "/Users/jaewonk/Documents/whoami/whoami-env-3.9/lib/python3.9/site-packages/rest_framework/mixins.py", line 56, in retrieve
    return Response(serializer.data)
  File "/Users/jaewonk/Documents/whoami/whoami-env-3.9/lib/python3.9/site-packages/rest_framework/serializers.py", line 555, in data
    ret = super().data
  File "/Users/jaewonk/Documents/whoami/whoami-env-3.9/lib/python3.9/site-packages/rest_framework/serializers.py", line 253, in data
    self._data = self.to_representation(self.instance)
  File "/Users/jaewonk/Documents/whoami/whoami-env-3.9/lib/python3.9/site-packages/rest_framework/serializers.py", line 507, in to_representation
    for field in fields:
  File "/Users/jaewonk/Documents/whoami/whoami-env-3.9/lib/python3.9/site-packages/rest_framework/serializers.py", line 368, in _readable_fields
    for field in self.fields.values():
  File "/Users/jaewonk/Documents/whoami/whoami-env-3.9/lib/python3.9/site-packages/django/utils/functional.py", line 57, in __get__
    res = instance.__dict__[self.name] = self.func(instance)
  File "/Users/jaewonk/Documents/whoami/whoami-env-3.9/lib/python3.9/site-packages/rest_framework/serializers.py", line 356, in fields
    for key, value in self.get_fields().items():
  File "/Users/jaewonk/Documents/whoami/whoami-env-3.9/lib/python3.9/site-packages/rest_framework/serializers.py", line 1076, in get_fields
    field_class, field_kwargs = self.build_field(
  File "/Users/jaewonk/Documents/whoami/whoami-env-3.9/lib/python3.9/site-packages/rest_framework/serializers.py", line 1222, in build_field
    return self.build_unknown_field(field_name, model_class)
  File "/Users/jaewonk/Documents/whoami/whoami-env-3.9/lib/python3.9/site-packages/rest_framework/serializers.py", line 1340, in build_unknown_field
    raise ImproperlyConfigured(
django.core.exceptions.ImproperlyConfigured: Field name `http://localhost:8000/media/profile_images/new_username.pngprofile_pic` is not valid for model `User`.
[35;1mHTTP GET /api/user/me/profile/ 500 [0.21, 127.0.0.1:64440][0m
Internal Server Error: /api/user/me/
Traceback (most recent call last):
  File "/Users/jaewonk/Documents/whoami/whoami-env-3.9/lib/python3.9/site-packages/django/db/backends/utils.py", line 89, in _execute
    return self.cursor.execute(sql, params)
psycopg2.errors.UniqueViolation: duplicate key value violates unique constraint "unique_active_username"
DETAIL:  Key (username)=(new_username) already exists.


The above exception was the direct cause of the following exception:

Traceback (most recent call last):
  File "/Users/jaewonk/Documents/whoami/whoami-env-3.9/lib/python3.9/site-packages/asgiref/sync.py", line 534, in thread_handler
    raise exc_info[1]
  File "/Users/jaewonk/Documents/whoami/whoami-env-3.9/lib/python3.9/site-packages/django/core/handlers/exception.py", line 42, in inner
    response = await get_response(request)
  File "/Users/jaewonk/Documents/whoami/whoami-env-3.9/lib/python3.9/site-packages/django/core/handlers/base.py", line 253, in _get_response_async
    response = await wrapped_callback(
  File "/Users/jaewonk/Documents/whoami/whoami-env-3.9/lib/python3.9/site-packages/asgiref/sync.py", line 479, in __call__
    ret: _R = await loop.run_in_executor(
  File "/Library/Developer/CommandLineTools/Library/Frameworks/Python3.framework/Versions/3.9/lib/python3.9/concurrent/futures/thread.py", line 52, in run
    result = self.fn(*self.args, **self.kwargs)
  File "/Users/jaewonk/Documents/whoami/whoami-env-3.9/lib/python3.9/site-packages/asgiref/sync.py", line 538, in thread_handler
    return func(*args, **kwargs)
  File "/Users/jaewonk/Documents/whoami/whoami-env-3.9/lib/python3.9/site-packages/django/views/decorators/csrf.py", line 56, in wrapper_view
    return view_func(*args, **kwargs)
  File "/Users/jaewonk/Documents/whoami/whoami-env-3.9/lib/python3.9/site-packages/django/views/generic/base.py", line 104, in view
    return self.dispatch(request, *args, **kwargs)
  File "/Users/jaewonk/Documents/whoami/whoami-env-3.9/lib/python3.9/site-packages/rest_framework/views.py", line 509, in dispatch
    response = self.handle_exception(exc)
  File "/Users/jaewonk/Documents/whoami/whoami-env-3.9/lib/python3.9/site-packages/rest_framework/views.py", line 469, in handle_exception
    self.raise_uncaught_exception(exc)
  File "/Users/jaewonk/Documents/whoami/whoami-env-3.9/lib/python3.9/site-packages/rest_framework/views.py", line 480, in raise_uncaught_exception
    raise exc
  File "/Users/jaewonk/Documents/whoami/whoami-env-3.9/lib/python3.9/site-packages/rest_framework/views.py", line 506, in dispatch
    response = handler(request, *args, **kwargs)
  File "/Users/jaewonk/Documents/whoami/whoami-env-3.9/lib/python3.9/site-packages/rest_framework/generics.py", line 258, in patch
    return self.partial_update(request, *args, **kwargs)
  File "/Users/jaewonk/Documents/whoami/whoami-env-3.9/lib/python3.9/site-packages/rest_framework/mixins.py", line 82, in partial_update
    return self.update(request, *args, **kwargs)
  File "/Users/jaewonk/Documents/whoami/whoami-env-3.9/lib/python3.9/site-packages/rest_framework/mixins.py", line 68, in update
    self.perform_update(serializer)
  File "/Library/Developer/CommandLineTools/Library/Frameworks/Python3.framework/Versions/3.9/lib/python3.9/contextlib.py", line 79, in inner
    return func(*args, **kwds)
  File "/Users/jaewonk/Documents/whoami/WhoAmI-Today-backend/adoorback/account/views.py", line 444, in perform_update
    serializer.save()
  File "/Users/jaewonk/Documents/whoami/whoami-env-3.9/lib/python3.9/site-packages/rest_framework/serializers.py", line 207, in save
    self.instance = self.update(self.instance, validated_data)
  File "/Users/jaewonk/Documents/whoami/whoami-env-3.9/lib/python3.9/site-packages/rest_framework/serializers.py", line 1006, in update
    instance.save()
  File "/Users/jaewonk/Documents/whoami/WhoAmI-Today-backend/adoorback/account/models.py", line 139, in save
    super().save(*args, **kwargs)
  File "/Users/jaewonk/Documents/whoami/whoami-env-3.9/lib/python3.9/site-packages/django/contrib/auth/base_user.py", line 76, in save
    super().save(*args, **kwargs)
  File "/Users/jaewonk/Documents/whoami/whoami-env-3.9/lib/python3.9/site-packages/safedelete/models.py", line 131, in save
    super(SafeDeleteModel, self).save(**kwargs)
  File "/Users/jaewonk/Documents/whoami/whoami-env-3.9/lib/python3.9/site-packages/django/db/models/base.py", line 814, in save
    self.save_base(
  File "/Users/jaewonk/Documents/whoami/whoami-env-3.9/lib/python3.9/site-packages/django/db/models/base.py", line 877, in save_base
    updated = self._save_table(
  File "/Users/jaewonk/Documents/whoami/whoami-env-3.9/lib/python3.9/site-packages/django/db/models/base.py", line 990, in _save_table
    updated = self._do_update(
  File "/Users/jaewonk/Documents/whoami/whoami-env-3.9/lib/python3.9/site-packages/django/db/models/base.py", line 1054, in _do_update
    return filtered._update(values) > 0
  File "/Users/jaewonk/Documents/whoami/whoami-env-3.9/lib/python3.9/site-packages/django/db/models/query.py", line 1231, in _update
    return query.get_compiler(self.db).execute_sql(CURSOR)
  File "/Users/jaewonk/Documents/whoami/whoami-env-3.9/lib/python3.9/site-packages/django/db/models/sql/compiler.py", line 1984, in execute_sql
    cursor = super().execute_sql(result_type)
  File "/Users/jaewonk/Documents/whoami/whoami-env-3.9/lib/python3.9/site-packages/django/db/models/sql/compiler.py", line 1562, in execute_sql
    cursor.execute(sql, params)
  File "/Users/jaewonk/Documents/whoami/whoami-env-3.9/lib/python3.9/site-packages/django/db/backends/utils.py", line 102, in execute
    return super().execute(sql, params)
  File "/Users/jaewonk/Documents/whoami/whoami-env-3.9/lib/python3.9/site-packages/django/db/backends/utils.py", line 67, in execute
    return self._execute_with_wrappers(
  File "/Users/jaewonk/Documents/whoami/whoami-env-3.9/lib/python3.9/site-packages/django/db/backends/utils.py", line 80, in _execute_with_wrappers
    return executor(sql, params, many, context)
  File "/Users/jaewonk/Documents/whoami/whoami-env-3.9/lib/python3.9/site-packages/django/db/backends/utils.py", line 89, in _execute
    return self.cursor.execute(sql, params)
  File "/Users/jaewonk/Documents/whoami/whoami-env-3.9/lib/python3.9/site-packages/django/db/utils.py", line 91, in __exit__
    raise dj_exc_value.with_traceback(traceback) from exc_value
  File "/Users/jaewonk/Documents/whoami/whoami-env-3.9/lib/python3.9/site-packages/django/db/backends/utils.py", line 89, in _execute
    return self.cursor.execute(sql, params)
django.db.utils.IntegrityError: duplicate key value violates unique constraint "unique_active_username"
DETAIL:  Key (username)=(new_username) already exists.

[35;1mHTTP PATCH /api/user/me/ 500 [0.49, 127.0.0.1:64615][0m
